<?xml version="1.0"?>
<robot name="/home/leanhchien/webots_ws/src/pioneer3dx/resource/pioneer3dx.urdf" xmlns:xacro="http://ros.org/wiki/xacro">
  <material name="blue">
    <color rgba="0 0 0.8 1"/>
  </material>
  <material name="black">
    <color rgba="0 0 0 1"/>
  </material>
  <material name="white">
    <color rgba="1 1 1 1"/>
  </material>  
  <material name="red">
    <color rgba="1 0 0 1"/>
  </material>  
  <material name="green">
    <color rgba="0 1 0 1"/>
  </material> 
  <!-- ****************** ROBOT WORLD ***************************  -->
  <!-- Define the center of the main robot chassis projected on the ground -->	
  <link name="world"/>

  <!-- The base footprint of the robot is located underneath the chassis -->
  <joint name="base_world" type="fixed">
    <parent link="world"/>
    <child link="base_footprint" />
    <origin xyz="0.0 0.0 0.0" rpy="0 0 0"/>
  </joint>
  <!-- ****************** ROBOT MAP ***************************  -->
  <!-- Define the center of the main robot chassis projected on the ground -->	
  <link name="map"/>

  <!-- The base footprint of the robot is located underneath the chassis -->
  <joint name="base_map" type="fixed">
    <parent link="world"/>
    <child link="map" />
    <origin xyz="-15.0 -15.0 0.0" rpy="0 0 0"/>
  </joint>
  <link name="base_footprint"/>

  <!-- The base footprint of the robot is located underneath the chassis -->
  <joint name="base_joint" type="fixed">
    <parent link="base_footprint"/>
    <child link="base_link" />
    <origin xyz="0.0 0.0 0.0957809" rpy="0 0 0"/>
  </joint>
  <!-- ********************** ROBOT BASE *********************************  -->
  <link name="base_link">
    <visual>
      <origin xyz="-0.021 0 0.142" rpy="0 0 -1.570796"/>
      <geometry>
        <cylinder radius="0.2" length="0.007"/>
      </geometry>
    </visual>
    <collision>
      <origin xyz="-0.021 0 0.142" rpy="0 0 -1.570796"/>
      <geometry>
        <cylinder radius="0.2" length="0.007"/>
      </geometry>
    </collision>
    <visual>
      <origin xyz="-0.087 0 0.142" rpy="0 0 -1.570796"/>
      <geometry>
        <cylinder radius="0.18" length="0.007"/>
      </geometry>
    </visual>
    <collision>
      <origin xyz="-0.087 0 0.142" rpy="0 0 -1.570796"/>
      <geometry>
        <cylinder radius="0.18" length="0.007"/>
      </geometry>
    </collision>
    <visual>
      <origin xyz="-0.114 0 0.112" rpy="0 0 -1.570796"/>
      <geometry>
        <cylinder radius="0.15" length="0.05"/>
      </geometry>
    </visual>
    <collision>
      <origin xyz="-0.114 0 0.112" rpy="0 0 -1.570796"/>
      <geometry>
        <cylinder radius="0.15" length="0.05"/>
      </geometry>
    </collision>
    <visual>
      <origin xyz="0.023 0 0.112" rpy="0 0 -1.570796"/>
      <geometry>
        <cylinder radius="0.15" length="0.05"/>
      </geometry>
    </visual>
    <collision>
      <origin xyz="0.023 0 0.112" rpy="0 0 -1.570796"/>
      <geometry>
        <cylinder radius="0.15" length="0.05"/>
      </geometry>
    </collision>
    <visual>
      <origin xyz="-0.04 0 0.0285" rpy="0 0 0"/>
      <geometry>
        <box size="0.341 0.2 0.115"/>
      </geometry>
    </visual>
    <collision>
      <origin xyz="-0.04 0 0.0285" rpy="0 0 0"/>
      <geometry>
        <box size="0.341 0.2 0.115"/>
      </geometry>
    </collision>
    <visual>
      <origin xyz="-0.234 0 0.0415" rpy="0 0 0"/>
      <geometry>
        <box size="0.039 0.1356 0.007"/>
      </geometry>
    </visual>
    <collision>
      <origin xyz="-0.234 0 0.0415" rpy="0 0 0"/>
      <geometry>
        <box size="0.039 0.1356 0.007"/>
      </geometry>
    </collision>
    <visual>
      <origin xyz="-0.0427 0 0.0285" rpy="0 0 0"/>
      <geometry>
        <box size="0.274 0.261 0.115"/>
      </geometry>
    </visual>
    <collision>
      <origin xyz="-0.0427 0 0.0285" rpy="0 0 0"/>
      <geometry>
        <box size="0.274 0.261 0.115"/>
      </geometry>
    </collision>
    <visual>
      <origin xyz="-0.1825 0.1029 0.0285" rpy="1.570797 0 -0.780796"/>
      <geometry>
        <box size="0.037 0.115 0.044"/>
      </geometry>
    </visual>
    <collision>
      <origin xyz="-0.1825 0.1029 0.0285" rpy="1.570797 0 -0.780796"/>
      <geometry>
        <box size="0.037 0.115 0.044"/>
      </geometry>
    </collision>
    <visual>
      <origin xyz="-0.1825 -0.1029 0.0285" rpy="1.570796 0 -2.360797"/>
      <geometry>
        <box size="0.037 0.115 0.044"/>
      </geometry>
    </visual>
    <collision>
      <origin xyz="-0.1825 -0.1029 0.0285" rpy="1.570796 0 -2.360797"/>
      <geometry>
        <box size="0.037 0.115 0.044"/>
      </geometry>
    </collision>
    <visual>
      <origin xyz="0.1005 0.1019 0.0285" rpy="1.570797 0.000001 -2.270796"/>
      <geometry>
        <box size="0.037 0.115 0.047"/>
      </geometry>
    </visual>
    <collision>
      <origin xyz="0.1005 0.1019 0.0285" rpy="1.570797 0.000001 -2.270796"/>
      <geometry>
        <box size="0.037 0.115 0.047"/>
      </geometry>
    </collision>
    <visual>
      <origin xyz="0.1005 -0.1019 0.0285" rpy="1.570796 0 -0.870797"/>
      <geometry>
        <box size="0.037 0.115 0.047"/>
      </geometry>
    </visual>
    <collision>
      <origin xyz="0.1005 -0.1019 0.0285" rpy="1.570796 0 -0.870797"/>
      <geometry>
        <box size="0.037 0.115 0.047"/>
      </geometry>
    </collision>
  </link>
  <!-- GPS -->
  <link name="gps">
    <visual>
      <geometry>
        <cylinder radius="0.01" length="0.01"/>
      </geometry>
      <material name="green"/>
    </visual>
    <collision>
      <geometry>
        <cylinder radius="0.01" length="0.01"/>
      </geometry>
    </collision>
  </link>
  <joint name="base_link_gps_joint" type="fixed">
    <parent link="base_link"/>
    <child link="gps"/>
    <origin xyz="0 0 0.15" rpy="0 0 0"/>
  </joint>
  <!-- IMU -->
  <link name="imu">
    <visual>
      <geometry>
        <cylinder radius="0.01" length="0.01"/>
      </geometry>
       <material name="green"/>
    </visual>
    <collision>
      <geometry>
        <cylinder radius="0.01" length="0.01"/>
      </geometry>
    </collision>
  </link>
  <joint name="base_link_imu_joint" type="fixed">
    <parent link="base_link"/>
    <child link="imu"/>
    <origin xyz="0.05 0 0.15" rpy="0 0 0"/>
  </joint>
  <!-- LiDAR -->
  <link name="lidar">
    <visual>
      <origin xyz="0 0 -0.017" rpy="1.570741 0.000118 -1.570741"/>
      <geometry>
        <box size="0.05 0.07 0.05"/>
      </geometry>
       <material name="black"/>
    </visual>
    <collision>
      <origin xyz="0 0 -0.017" rpy="1.570741 0.000118 -1.570741"/>
      <geometry>
        <box size="0.05 0.07 0.05"/>
      </geometry>
    </collision>
  </link>
  <joint name="base_link_lidar_joint" type="fixed">
    <parent link="base_link"/>
    <child link="lidar"/>
    <origin xyz="0 0 0.19" rpy="0 0 0"/>
  </joint>
  <!-- Right wheel -->
  <joint name="right wheel" type="continuous">
    <parent link="base_link"/>
    <child link="right wheel"/>
    <axis xyz="-1 0 0"/>
    <limit effort="10" velocity="12.3"/>
    <origin xyz="0 -0.165 0" rpy="1.570796 0 -1.570796"/>
  </joint>
  <link name="right wheel">
    <visual>
      <origin xyz="0 0 0" rpy="-1.570796 0 1.5708"/>
      <geometry>
        <cylinder radius="0.0975" length="0.01"/>
      </geometry>
       <material name="black"/>
    </visual>
    <collision>
      <origin xyz="0 0 0" rpy="-1.570796 0 1.5708"/>
      <geometry>
        <cylinder radius="0.0975" length="0.01"/>
      </geometry>
    </collision>
    <visual>
      <origin xyz="0 0 0" rpy="-1.570796 0 1.5708"/>
      <geometry>
        <cylinder radius="0.07" length="0.048"/>
      </geometry>
    </visual>
    <collision>
      <origin xyz="0 0 0" rpy="-1.570796 0 1.5708"/>
      <geometry>
        <cylinder radius="0.07" length="0.048"/>
      </geometry>
    </collision>
  </link>
  <!-- Left wheel -->
  <joint name="left wheel" type="continuous">
    <parent link="base_link"/>
    <child link="left wheel"/>
    <axis xyz="-1 0 0"/>
    <limit effort="10" velocity="12.3"/>
    <origin xyz="0 0.165 0" rpy="1.570796 0 -1.570796"/>
  </joint>
  <link name="left wheel">
    <visual>
      <origin xyz="0 0 0" rpy="-1.570796 0 1.5708"/>
      <geometry>
        <cylinder radius="0.0975" length="0.01"/>
      </geometry>
       <material name="black"/>
    </visual>
    <collision>
      <origin xyz="0 0 0" rpy="-1.570796 0 1.5708"/>
      <geometry>
        <cylinder radius="0.0975" length="0.01"/>
      </geometry>
    </collision>
    <visual>
      <origin xyz="0 0 0" rpy="-1.570796 0 1.5708"/>
      <geometry>
        <cylinder radius="0.07" length="0.048"/>
      </geometry>
    </visual>
    <collision>
      <origin xyz="0 0 0" rpy="-1.570796 0 1.5708"/>
      <geometry>
        <cylinder radius="0.07" length="0.048"/>
      </geometry>
    </collision>
  </link>
  <!-- Caster wheel -->
  <joint name="CASTER_WHEEL" type="continuous">
    <parent link="base_link"/>
    <child link="caster wheel"/>
    <axis xyz="0 1 0"/>
    <origin xyz="-0.1918 0 0" rpy="1.570796 0 -1.570796"/>
  </joint>
  <link name="caster wheel">
    <visual>
      <origin xyz="0 -0.032 0.0031" rpy="1.25 0 0"/>
      <geometry>
        <box size="0.05 0.028 0.067"/>
      </geometry>
      <material name="black"/>
    </visual>
    <collision>
      <origin xyz="0 -0.032 0.0031" rpy="1.25 0 0"/>
      <geometry>
        <box size="0.05 0.028 0.067"/>
      </geometry>
    </collision>
  </link>
  <joint name="casterWheelRim" type="continuous">
    <parent link="caster wheel"/>
    <child link="solid"/>
    <axis xyz="1 0 0"/>
    <origin xyz="0 -0.052101 0.012843" rpy="0 0 0"/>
  </joint>
  <link name="solid">
    <visual>
      <origin xyz="0 0 0" rpy="-1.570796 0 1.5708"/>
      <geometry>
        <cylinder radius="0.0375" length="0.025"/>
      </geometry>
      <material name="black"/>
    </visual>
    <collision>
      <origin xyz="0 0 0" rpy="-1.570796 0 1.5708"/>
      <geometry>
        <cylinder radius="0.0375" length="0.025"/>
      </geometry>
    </collision>
  </link>
</robot>
